<sdf version='1.6'>
  <world name='default'>
    <light name='sun' type='directional'>
      <cast_shadows>1</cast_shadows>
      <pose frame=''>0 0 10 0 -0 0</pose>
      <diffuse>0.8 0.8 0.8 1</diffuse>
      <specular>0.1 0.1 0.1 1</specular>
      <attenuation>
        <range>1000</range>
        <constant>0.9</constant>
        <linear>0.01</linear>
        <quadratic>0.001</quadratic>
      </attenuation>
      <direction>-0.5 0.5 -1</direction>
    </light>
    <model name='ground_plane'>
      <static>1</static>
      <link name='link'>
        <collision name='collision'>
          <geometry>
            <plane>
              <normal>0 0 1</normal>
              <size>100 100</size>
            </plane>
          </geometry>
          <surface>
            <friction>
              <ode>
                <mu>100</mu>
                <mu2>50</mu2>
              </ode>
              <torsional>
                <ode/>
              </torsional>
            </friction>
            <contact>
              <ode/>
            </contact>
            <bounce/>
          </surface>
          <max_contacts>10</max_contacts>
        </collision>
        <visual name='visual'>
          <cast_shadows>0</cast_shadows>
          <geometry>
            <plane>
              <normal>0 0 1</normal>
              <size>100 100</size>
            </plane>
          </geometry>
          <material>
            <script>
              <uri>file://media/materials/scripts/gazebo.material</uri>
              <name>Gazebo/Grey</name>
            </script>
          </material>
        </visual>
        <self_collide>0</self_collide>
        <kinematic>0</kinematic>
        <gravity>1</gravity>
      </link>
    </model>
    <gravity>0 0 -9.8</gravity>
    <magnetic_field>6e-06 2.3e-05 -4.2e-05</magnetic_field>
    <atmosphere type='adiabatic'/>
    <physics name='default_physics' default='0' type='ode'>
      <max_step_size>0.001</max_step_size>
      <real_time_factor>1</real_time_factor>
      <real_time_update_rate>1000</real_time_update_rate>
    </physics>
    <scene>
      <ambient>0.4 0.4 0.4 1</ambient>
      <background>0.7 0.7 0.7 1</background>
      <shadows>1</shadows>
    </scene>
    <spherical_coordinates>
      <surface_model>EARTH_WGS84</surface_model>
      <latitude_deg>0</latitude_deg>
      <longitude_deg>0</longitude_deg>
      <elevation>0</elevation>
      <heading_deg>0</heading_deg>
    </spherical_coordinates>
    <model name='quadrotor'>
      <link name='base_link'>
        <pose frame=''>0 0 0 0 -0 0</pose>
        <inertial>
          <pose frame=''>-0.000213 0 -0.018164 0 -0 0</pose>
          <mass>1.6723</mass>
          <inertia>
            <ixx>0.0174285</ixx>
            <ixy>-9.95804e-10</ixy>
            <ixz>3.9741e-06</ixz>
            <iyy>0.02</iyy>
            <iyz>-1.25578e-10</iyz>
            <izz>0.0329446</izz>
          </inertia>
        </inertial>
        <collision name='base_link_collision'>
          <pose frame=''>0 0 0 0 -0 0</pose>
          <geometry>
            <mesh>
              <scale>1 1 1</scale>
              <uri>/home/rahul/catkin_ws/src/sprayer_drone/meshes/base_link.STL</uri>
            </mesh>
          </geometry>
          <max_contacts>10</max_contacts>
          <surface>
            <contact>
              <ode/>
            </contact>
            <bounce/>
            <friction>
              <torsional>
                <ode/>
              </torsional>
              <ode/>
            </friction>
          </surface>
        </collision>
        <collision name='base_link_fixed_joint_lump__laser0_frame_collision_1'>
          <pose frame=''>0 -0 -0.0855 -3.14159 -0 0</pose>
          <geometry>
            <box>
              <size>0.058 0.058 0.087</size>
            </box>
          </geometry>
          <surface>
            <contact>
              <ode/>
            </contact>
            <friction>
              <ode/>
              <torsional>
                <ode/>
              </torsional>
            </friction>
            <bounce/>
          </surface>
          <max_contacts>10</max_contacts>
        </collision>
        <collision name='base_link_fixed_joint_lump__sonar_link_collision_2'>
          <pose frame=''>-0.16 0 -0.012 3.14159 1.57079 3.14159</pose>
          <geometry>
            <box>
              <size>0.01 0.01 0.01</size>
            </box>
          </geometry>
          <surface>
            <contact>
              <ode/>
            </contact>
            <friction>
              <ode/>
              <torsional>
                <ode/>
              </torsional>
            </friction>
            <bounce/>
          </surface>
          <max_contacts>10</max_contacts>
        </collision>
        <visual name='base_link_visual'>
          <pose frame=''>0 0 0 0 -0 0</pose>
          <geometry>
            <mesh>
              <scale>1 1 1</scale>
              <uri>/home/rahul/catkin_ws/src/sprayer_drone/meshes/base_link.STL</uri>
            </mesh>
          </geometry>
        </visual>
        <visual name='base_link_fixed_joint_lump__laser0_frame_visual_1'>
          <pose frame=''>0 0 -0.097 -3.14159 -0 0</pose>
          <geometry>
            <mesh>
              <scale>1 1 1</scale>
              <uri>/home/rahul/catkin_ws/src/hector_quadrotor_sim/hector_models/hector_sensors_description/meshes/hokuyo_utm30lx/hokuyo_utm_30lxTEST_SELF_FILTER.dae</uri>
            </mesh>
          </geometry>
          <material>
            <script>
              <uri>__default__</uri>
              <name>__default__</name>
            </script>
          </material>
        </visual>
        <visual name='base_link_fixed_joint_lump__sonar_link_visual_2'>
          <pose frame=''>-0.16 0 -0.012 3.14159 1.57079 3.14159</pose>
          <geometry>
            <mesh>
              <scale>1 1 1</scale>
              <uri>/home/rahul/catkin_ws/src/hector_quadrotor_sim/hector_models/hector_sensors_description/meshes/sonar_sensor/max_sonar_ez4.dae</uri>
            </mesh>
          </geometry>
          <material>
            <script>
              <uri>__default__</uri>
              <name>__default__</name>
            </script>
          </material>
        </visual>
        <velocity_decay/>
        <sensor name='front_cam_camera_sensor' type='camera'>
          <update_rate>10</update_rate>
          <camera name='__default__'>
            <horizontal_fov>1.5708</horizontal_fov>
            <image>
              <format>R8G8B8</format>
              <width>320</width>
              <height>240</height>
            </image>
            <clip>
              <near>0.01</near>
              <far>100</far>
            </clip>
          </camera>
          <plugin name='front_cam_camera_controller' filename='libgazebo_ros_camera.so'>
            <cameraName>front_cam</cameraName>
            <imageTopicName>camera/image</imageTopicName>
            <cameraInfoTopicName>camera/camera_info</cameraInfoTopicName>
            <frameName>front_cam_optical_frame</frameName>
            <robotNamespace>/</robotNamespace>
          </plugin>
          <pose frame=''>0.05 0 -0.06 0 -0 0</pose>
        </sensor>
        <velocity_decay/>
        <sensor name='laser0' type='ray'>
          <always_on>1</always_on>
          <update_rate>40</update_rate>
          <visualize>0</visualize>
          <ray>
            <scan>
              <horizontal>
                <samples>1081</samples>
                <resolution>1</resolution>
                <min_angle>-2.35619</min_angle>
                <max_angle>2.35619</max_angle>
              </horizontal>
              <vertical>
                <samples>1</samples>
                <min_angle>0</min_angle>
                <max_angle>0</max_angle>
              </vertical>
            </scan>
            <range>
              <min>0.08</min>
              <max>30</max>
              <resolution>0.01</resolution>
            </range>
            <noise>
              <type>gaussian</type>
              <mean>0</mean>
              <stddev>0.004</stddev>
            </noise>
          </ray>
          <plugin name='gazebo_ros_laser0_controller' filename='libgazebo_ros_laser.so'>
            <topicName>scan</topicName>
            <frameName>laser0_frame</frameName>
            <robotNamespace>/</robotNamespace>
          </plugin>
          <pose frame=''>0 0 -0.097 -3.14159 -0 0</pose>
        </sensor>
        <gravity>1</gravity>
        <velocity_decay/>
        <self_collide>0</self_collide>
        <sensor name='sonar' type='ray'>
          <always_on>1</always_on>
          <update_rate>10</update_rate>
          <visualize>0</visualize>
          <ray>
            <scan>
              <horizontal>
                <samples>3</samples>
                <resolution>1</resolution>
                <min_angle>-0.349066</min_angle>
                <max_angle>0.349066</max_angle>
              </horizontal>
              <vertical>
                <samples>3</samples>
                <resolution>1</resolution>
                <min_angle>-0.349066</min_angle>
                <max_angle>0.349066</max_angle>
              </vertical>
            </scan>
            <range>
              <min>0.03</min>
              <max>3</max>
              <resolution>0.01</resolution>
            </range>
          </ray>
          <plugin name='gazebo_ros_sonar_controller' filename='libhector_gazebo_ros_sonar.so'>
            <gaussianNoise>0.005</gaussianNoise>
            <topicName>sonar_height</topicName>
            <frameId>sonar_link</frameId>
            <robotNamespace>/</robotNamespace>
          </plugin>
          <pose frame=''>-0.16 0 -0.012 3.14159 1.57079 3.14159</pose>
        </sensor>
        <kinematic>0</kinematic>
      </link>
      <link name='prop1'>
        <pose frame=''>-0.43301 -0.25 0.004486 1.5708 -0 0</pose>
        <inertial>
          <pose frame=''>0 0.007038 0 0 -0 0</pose>
          <mass>0.026553</mass>
          <inertia>
            <ixx>4.8335e-07</ixx>
            <ixy>-6.0245e-22</ixy>
            <ixz>-1.1374e-21</ixz>
            <iyy>0.00039871</iyy>
            <iyz>5.8633e-23</iyz>
            <izz>0.00039845</izz>
          </inertia>
        </inertial>
        <collision name='prop1_collision'>
          <pose frame=''>0 0 0 0 -0 0</pose>
          <geometry>
            <mesh>
              <scale>1 1 1</scale>
              <uri>/home/rahul/catkin_ws/src/sprayer_drone/meshes/prop1.STL</uri>
            </mesh>
          </geometry>
          <max_contacts>10</max_contacts>
          <surface>
            <contact>
              <ode/>
            </contact>
            <bounce/>
            <friction>
              <torsional>
                <ode/>
              </torsional>
              <ode/>
            </friction>
          </surface>
        </collision>
        <visual name='prop1_visual'>
          <pose frame=''>0 0 0 0 -0 0</pose>
          <geometry>
            <mesh>
              <scale>1 1 1</scale>
              <uri>/home/rahul/catkin_ws/src/sprayer_drone/meshes/prop1.STL</uri>
            </mesh>
          </geometry>
        </visual>
        <self_collide>0</self_collide>
        <kinematic>0</kinematic>
        <gravity>1</gravity>
      </link>
      <joint name='motor1' type='revolute'>
        <child>prop1</child>
        <parent>base_link</parent>
        <axis>
          <xyz>0 -4e-06 1</xyz>
          <limit>
            <lower>-1e+16</lower>
            <upper>1e+16</upper>
          </limit>
          <dynamics>
            <spring_reference>0</spring_reference>
            <spring_stiffness>0</spring_stiffness>
          </dynamics>
          <use_parent_model_frame>1</use_parent_model_frame>
        </axis>
      </joint>
      <link name='prop2'>
        <pose frame=''>-0.43301 0.25 0.0053 1.5708 -0 0</pose>
        <inertial>
          <pose frame=''>0 0.007038 0 0 -0 0</pose>
          <mass>0.026553</mass>
          <inertia>
            <ixx>4.8335e-07</ixx>
            <ixy>-2.068e-22</ixy>
            <ixz>-3.6786e-21</ixz>
            <iyy>0.00039871</iyy>
            <iyz>-1.2047e-22</iyz>
            <izz>0.00039845</izz>
          </inertia>
        </inertial>
        <collision name='prop2_collision'>
          <pose frame=''>0 0 0 0 -0 0</pose>
          <geometry>
            <mesh>
              <scale>1 1 1</scale>
              <uri>/home/rahul/catkin_ws/src/sprayer_drone/meshes/prop2.STL</uri>
            </mesh>
          </geometry>
          <max_contacts>10</max_contacts>
          <surface>
            <contact>
              <ode/>
            </contact>
            <bounce/>
            <friction>
              <torsional>
                <ode/>
              </torsional>
              <ode/>
            </friction>
          </surface>
        </collision>
        <visual name='prop2_visual'>
          <pose frame=''>0 0 0 0 -0 0</pose>
          <geometry>
            <mesh>
              <scale>1 1 1</scale>
              <uri>/home/rahul/catkin_ws/src/sprayer_drone/meshes/prop2.STL</uri>
            </mesh>
          </geometry>
        </visual>
        <self_collide>0</self_collide>
        <kinematic>0</kinematic>
        <gravity>1</gravity>
      </link>
      <joint name='motor2' type='revolute'>
        <child>prop2</child>
        <parent>base_link</parent>
        <axis>
          <xyz>0 -4e-06 1</xyz>
          <limit>
            <lower>-1e+16</lower>
            <upper>1e+16</upper>
          </limit>
          <dynamics>
            <spring_reference>0</spring_reference>
            <spring_stiffness>0</spring_stiffness>
          </dynamics>
          <use_parent_model_frame>1</use_parent_model_frame>
        </axis>
      </joint>
      <link name='prop3'>
        <pose frame=''>0 0.5 0.005 1.5708 -0 0</pose>
        <inertial>
          <pose frame=''>0 0.007038 0 0 -0 0</pose>
          <mass>0.026553</mass>
          <inertia>
            <ixx>4.8335e-07</ixx>
            <ixy>1.3267e-22</ixy>
            <ixz>-1.1374e-21</ixz>
            <iyy>0.00039871</iyy>
            <iyz>3.0132e-23</iyz>
            <izz>0.00039845</izz>
          </inertia>
        </inertial>
        <collision name='prop3_collision'>
          <pose frame=''>0 0 0 0 -0 0</pose>
          <geometry>
            <mesh>
              <scale>1 1 1</scale>
              <uri>/home/rahul/catkin_ws/src/sprayer_drone/meshes/prop3.STL</uri>
            </mesh>
          </geometry>
          <max_contacts>10</max_contacts>
          <surface>
            <contact>
              <ode/>
            </contact>
            <bounce/>
            <friction>
              <torsional>
                <ode/>
              </torsional>
              <ode/>
            </friction>
          </surface>
        </collision>
        <visual name='prop3_visual'>
          <pose frame=''>0 0 0 0 -0 0</pose>
          <geometry>
            <mesh>
              <scale>1 1 1</scale>
              <uri>/home/rahul/catkin_ws/src/sprayer_drone/meshes/prop3.STL</uri>
            </mesh>
          </geometry>
        </visual>
        <self_collide>0</self_collide>
        <kinematic>0</kinematic>
        <gravity>1</gravity>
      </link>
      <joint name='motor3' type='revolute'>
        <child>prop3</child>
        <parent>base_link</parent>
        <axis>
          <xyz>0 -4e-06 1</xyz>
          <limit>
            <lower>-1e+16</lower>
            <upper>1e+16</upper>
          </limit>
          <dynamics>
            <spring_reference>0</spring_reference>
            <spring_stiffness>0</spring_stiffness>
          </dynamics>
          <use_parent_model_frame>1</use_parent_model_frame>
        </axis>
      </joint>
      <link name='prop4'>
        <pose frame=''>0.43301 0.25 0.005 1.5708 -0 0</pose>
        <inertial>
          <pose frame=''>0 0.007038 0 0 -0 0</pose>
          <mass>0.026553</mass>
          <inertia>
            <ixx>4.8335e-07</ixx>
            <ixy>-6.6984e-22</ixy>
            <ixz>-3.9291e-21</ixz>
            <iyy>0.00039871</iyy>
            <iyz>-2.9509e-24</iyz>
            <izz>0.00039845</izz>
          </inertia>
        </inertial>
        <collision name='prop4_collision'>
          <pose frame=''>0 0 0 0 -0 0</pose>
          <geometry>
            <mesh>
              <scale>1 1 1</scale>
              <uri>/home/rahul/catkin_ws/src/sprayer_drone/meshes/prop4.STL</uri>
            </mesh>
          </geometry>
          <max_contacts>10</max_contacts>
          <surface>
            <contact>
              <ode/>
            </contact>
            <bounce/>
            <friction>
              <torsional>
                <ode/>
              </torsional>
              <ode/>
            </friction>
          </surface>
        </collision>
        <visual name='prop4_visual'>
          <pose frame=''>0 0 0 0 -0 0</pose>
          <geometry>
            <mesh>
              <scale>1 1 1</scale>
              <uri>/home/rahul/catkin_ws/src/sprayer_drone/meshes/prop4.STL</uri>
            </mesh>
          </geometry>
        </visual>
        <self_collide>0</self_collide>
        <kinematic>0</kinematic>
        <gravity>1</gravity>
      </link>
      <joint name='motor4' type='revolute'>
        <child>prop4</child>
        <parent>base_link</parent>
        <axis>
          <xyz>0 -4e-06 1</xyz>
          <limit>
            <lower>-1e+16</lower>
            <upper>1e+16</upper>
          </limit>
          <dynamics>
            <spring_reference>0</spring_reference>
            <spring_stiffness>0</spring_stiffness>
          </dynamics>
          <use_parent_model_frame>1</use_parent_model_frame>
        </axis>
      </joint>
      <link name='prop5'>
        <pose frame=''>0.43301 -0.25 0.005903 1.5708 -0 0</pose>
        <inertial>
          <pose frame=''>0 0.007038 0 0 -0 0</pose>
          <mass>0.026553</mass>
          <inertia>
            <ixx>4.8335e-07</ixx>
            <ixy>-6.2935e-22</ixy>
            <ixz>-3.9291e-21</ixz>
            <iyy>0.00039871</iyy>
            <iyz>-1.9037e-23</iyz>
            <izz>0.00039845</izz>
          </inertia>
        </inertial>
        <collision name='prop5_collision'>
          <pose frame=''>0 0 0 0 -0 0</pose>
          <geometry>
            <mesh>
              <scale>1 1 1</scale>
              <uri>/home/rahul/catkin_ws/src/sprayer_drone/meshes/prop5.STL</uri>
            </mesh>
          </geometry>
          <max_contacts>10</max_contacts>
          <surface>
            <contact>
              <ode/>
            </contact>
            <bounce/>
            <friction>
              <torsional>
                <ode/>
              </torsional>
              <ode/>
            </friction>
          </surface>
        </collision>
        <visual name='prop5_visual'>
          <pose frame=''>0 0 0 0 -0 0</pose>
          <geometry>
            <mesh>
              <scale>1 1 1</scale>
              <uri>/home/rahul/catkin_ws/src/sprayer_drone/meshes/prop5.STL</uri>
            </mesh>
          </geometry>
        </visual>
        <self_collide>0</self_collide>
        <kinematic>0</kinematic>
        <gravity>1</gravity>
      </link>
      <joint name='motor5' type='revolute'>
        <child>prop5</child>
        <parent>base_link</parent>
        <axis>
          <xyz>0 -4e-06 1</xyz>
          <limit>
            <lower>-1e+16</lower>
            <upper>1e+16</upper>
          </limit>
          <dynamics>
            <spring_reference>0</spring_reference>
            <spring_stiffness>0</spring_stiffness>
          </dynamics>
          <use_parent_model_frame>1</use_parent_model_frame>
        </axis>
      </joint>
      <link name='prop6'>
        <pose frame=''>0 -0.5 0.006073 1.5708 -0 0</pose>
        <inertial>
          <pose frame=''>0 0.007038 0 0 -0 0</pose>
          <mass>0.026553</mass>
          <inertia>
            <ixx>4.8335e-07</ixx>
            <ixy>1.8886e-22</ixy>
            <ixz>-1.1374e-21</ixz>
            <iyy>0.00039871</iyy>
            <iyz>2.9972e-23</iyz>
            <izz>0.00039845</izz>
          </inertia>
        </inertial>
        <collision name='prop6_collision'>
          <pose frame=''>0 0 0 0 -0 0</pose>
          <geometry>
            <mesh>
              <scale>1 1 1</scale>
              <uri>/home/rahul/catkin_ws/src/sprayer_drone/meshes/prop6.STL</uri>
            </mesh>
          </geometry>
          <max_contacts>10</max_contacts>
          <surface>
            <contact>
              <ode/>
            </contact>
            <bounce/>
            <friction>
              <torsional>
                <ode/>
              </torsional>
              <ode/>
            </friction>
          </surface>
        </collision>
        <visual name='prop6_visual'>
          <pose frame=''>0 0 0 0 -0 0</pose>
          <geometry>
            <mesh>
              <scale>1 1 1</scale>
              <uri>/home/rahul/catkin_ws/src/sprayer_drone/meshes/prop6.STL</uri>
            </mesh>
          </geometry>
        </visual>
        <self_collide>0</self_collide>
        <kinematic>0</kinematic>
        <gravity>1</gravity>
      </link>
      <joint name='motor6' type='revolute'>
        <child>prop6</child>
        <parent>base_link</parent>
        <axis>
          <xyz>0 -4e-06 1</xyz>
          <limit>
            <lower>-1e+16</lower>
            <upper>1e+16</upper>
          </limit>
          <dynamics>
            <spring_reference>0</spring_reference>
            <spring_stiffness>0</spring_stiffness>
          </dynamics>
          <use_parent_model_frame>1</use_parent_model_frame>
        </axis>
      </joint>
      <plugin name='quadrotor_imu_sim' filename='libhector_gazebo_ros_imu.so'>
        <updateRate>100.0</updateRate>
        <bodyName>base_link</bodyName>
        <frameId>/base_link</frameId>
        <topicName>raw_imu</topicName>
        <rpyOffset>0 0 0</rpyOffset>
        <gaussianNoise>0</gaussianNoise>
        <accelDrift>0.5 0.5 0.5</accelDrift>
        <accelGaussianNoise>0.35 0.35 0.3</accelGaussianNoise>
        <rateDrift>0.1 0.1 0.1</rateDrift>
        <rateGaussianNoise>0.05 0.05 0.015</rateGaussianNoise>
        <robotNamespace>/</robotNamespace>
      </plugin>
      <plugin name='quadrotor_baro_sim' filename='libhector_gazebo_ros_baro.so'>
        <updateRate>10.0</updateRate>
        <bodyName>base_link</bodyName>
        <frameId>/base_link</frameId>
        <topicName>pressure_height</topicName>
        <altimeterTopicName>altimeter</altimeterTopicName>
        <offset>0</offset>
        <drift>10.0</drift>
        <gaussianNoise>0.1</gaussianNoise>
        <robotNamespace>/</robotNamespace>
      </plugin>
      <plugin name='quadrotor_magnetic_sim' filename='libhector_gazebo_ros_magnetic.so'>
        <updateRate>10.0</updateRate>
        <bodyName>base_link</bodyName>
        <frameId>/base_link</frameId>
        <topicName>magnetic</topicName>
        <offset>0 0 0</offset>
        <drift>0.0 0.0 0.0</drift>
        <gaussianNoise>1.3e-2 1.3e-2 1.3e-2</gaussianNoise>
        <robotNamespace>/</robotNamespace>
      </plugin>
      <plugin name='quadrotor_gps_sim' filename='libhector_gazebo_ros_gps.so'>
        <updateRate>4.0</updateRate>
        <bodyName>base_link</bodyName>
        <frameId>/base_link</frameId>
        <topicName>fix</topicName>
        <velocityTopicName>fix_velocity</velocityTopicName>
        <referenceLatitude>49.860246</referenceLatitude>
        <referenceLongitude>8.687077</referenceLongitude>
        <drift>5.0 5.0 5.0</drift>
        <gaussianNoise>0.01 0.01 0.01</gaussianNoise>
        <velocityDrift>0 0 0</velocityDrift>
        <velocityGaussianNoise>0.05 0.05 0.05</velocityGaussianNoise>
        <robotNamespace>/</robotNamespace>
      </plugin>
      <plugin name='quadrotor_groundtruth_sim' filename='libgazebo_ros_p3d.so'>
        <updateRate>100.0</updateRate>
        <bodyName>base_link</bodyName>
        <topicName>ground_truth/state</topicName>
        <gaussianNoise>0.0</gaussianNoise>
        <frameName>world</frameName>
        <robotNamespace>/</robotNamespace>
      </plugin>
      <plugin name='quadrotor_controller' filename='libgazebo_ros_control.so'>
        <controlPeriod>0.01</controlPeriod>
        <robotSimType>hector_quadrotor_controller_gazebo/QuadrotorHardwareSim</robotSimType>
        <robotNamespace>/</robotNamespace>
      </plugin>
      <plugin name='quadrotor_propulsion' filename='libhector_gazebo_quadrotor_propulsion.so'>
        <alwaysOn>true</alwaysOn>
        <updateRate>0.0</updateRate>
        <bodyName>base_link</bodyName>
        <frameId>/base_link</frameId>
        <controlRate>100.0</controlRate>
        <controlDelay>0.01</controlDelay>
        <motorStatusRate>100.0</motorStatusRate>
        <robotNamespace>/</robotNamespace>
      </plugin>
      <static>0</static>
      <plugin name='quadrotor_aerodynamics' filename='libhector_gazebo_quadrotor_aerodynamics.so'>
        <alwaysOn>true</alwaysOn>
        <updateRate>0.0</updateRate>
        <bodyName>base_link</bodyName>
        <frameId>/base_link</frameId>
        <robotNamespace>/</robotNamespace>
      </plugin>
      <pose frame=''>0 0 0.3 0 -0 0</pose>
    </model>
    <model name='baylands_01'>
      <pose frame=''>28.9014 -21.3422 -1.3 0 -0 0</pose>
      <static>1</static>
      <link name='body'>
        <visual name='visual'>
          <geometry>
            <mesh>
              <uri>model://baylands/media/baylands_01.DAE</uri>
              <scale>1 1 1</scale>
            </mesh>
          </geometry>
          <material>
            <script>
              <uri>model://baylands/media/scripts/</uri>
              <uri>model://baylands/media/Textures/</uri>
              <name>OakTree/Branch</name>
            </script>
          </material>
        </visual>
        <collision name='collision'>
          <geometry>
            <mesh>
              <uri>model://baylands/media/baylands_01.DAE</uri>
              <scale>1 1 1</scale>
            </mesh>
          </geometry>
          <max_contacts>10</max_contacts>
          <surface>
            <contact>
              <ode/>
            </contact>
            <bounce/>
            <friction>
              <torsional>
                <ode/>
              </torsional>
              <ode/>
            </friction>
          </surface>
        </collision>
        <self_collide>0</self_collide>
        <kinematic>0</kinematic>
        <gravity>1</gravity>
      </link>
      <link name='body2'>
        <visual name='visual'>
          <geometry>
            <mesh>
              <uri>model://baylands/media/baylands_02.DAE</uri>
              <scale>1 1 1</scale>
            </mesh>
          </geometry>
          <material>
            <script>
              <uri>model://baylands/media/scripts/</uri>
              <uri>model://baylands/media/Textures/</uri>
              <name>OakTree/Branch</name>
            </script>
          </material>
        </visual>
        <collision name='collision'>
          <geometry>
            <mesh>
              <uri>model://baylands/media/baylands_02.DAE</uri>
              <scale>1 1 1</scale>
            </mesh>
          </geometry>
          <max_contacts>10</max_contacts>
          <surface>
            <contact>
              <ode/>
            </contact>
            <bounce/>
            <friction>
              <torsional>
                <ode/>
              </torsional>
              <ode/>
            </friction>
          </surface>
        </collision>
        <self_collide>0</self_collide>
        <kinematic>0</kinematic>
        <gravity>1</gravity>
      </link>
      <link name='body3'>
        <visual name='visual'>
          <geometry>
            <mesh>
              <uri>model://baylands/media/baylands_03.DAE</uri>
              <scale>1 1 1</scale>
            </mesh>
          </geometry>
        </visual>
        <collision name='collision'>
          <geometry>
            <mesh>
              <uri>model://baylands/media/baylands_03.DAE</uri>
              <scale>1 1 1</scale>
            </mesh>
          </geometry>
          <max_contacts>10</max_contacts>
          <surface>
            <contact>
              <ode/>
            </contact>
            <bounce/>
            <friction>
              <torsional>
                <ode/>
              </torsional>
              <ode/>
            </friction>
          </surface>
        </collision>
        <self_collide>0</self_collide>
        <kinematic>0</kinematic>
        <gravity>1</gravity>
      </link>
    </model>
    <state world_name='default'>
      <sim_time>60 683000000</sim_time>
      <real_time>91 972025013</real_time>
      <wall_time>1633863707 160821821</wall_time>
      <iterations>60683</iterations>
      <model name='baylands_01'>
        <pose frame=''>28.9014 -21.3422 -1.3 0 -0 0</pose>
        <scale>1 1 1</scale>
        <link name='body'>
          <pose frame=''>28.9014 -21.3422 -1.3 0 -0 0</pose>
          <velocity>0 0 0 0 -0 0</velocity>
          <acceleration>0 0 0 0 -0 0</acceleration>
          <wrench>0 0 0 0 -0 0</wrench>
        </link>
        <link name='body2'>
          <pose frame=''>28.9014 -21.3422 -1.3 0 -0 0</pose>
          <velocity>0 0 0 0 -0 0</velocity>
          <acceleration>0 0 0 0 -0 0</acceleration>
          <wrench>0 0 0 0 -0 0</wrench>
        </link>
        <link name='body3'>
          <pose frame=''>28.9014 -21.3422 -1.3 0 -0 0</pose>
          <velocity>0 0 0 0 -0 0</velocity>
          <acceleration>0 0 0 0 -0 0</acceleration>
          <wrench>0 0 0 0 -0 0</wrench>
        </link>
      </model>
      <model name='ground_plane'>
        <pose frame=''>0 0 0 0 -0 0</pose>
        <scale>1 1 1</scale>
        <link name='link'>
          <pose frame=''>0 0 0 0 -0 0</pose>
          <velocity>0 0 0 0 -0 0</velocity>
          <acceleration>0 0 0 0 -0 0</acceleration>
          <wrench>0 0 0 0 -0 0</wrench>
        </link>
      </model>
      <model name='quadrotor'>
        <pose frame=''>4e-06 6e-06 0.128992 -3e-05 5e-06 -0.000859</pose>
        <scale>1 1 1</scale>
        <link name='base_link'>
          <pose frame=''>4e-06 6e-06 0.128992 -3e-05 5e-06 -0.000859</pose>
          <velocity>0.000613 0.000913 -0.008944 -0.007065 0.004694 0.00026</velocity>
          <acceleration>0.000151 -5e-06 -9.79995 0.000464 -0.002497 0.025737</acceleration>
          <wrench>0.000252 -9e-06 -16.3885 0 -0 0</wrench>
        </link>
        <link name='prop1'>
          <pose frame=''>-0.43322 -0.249622 0.133487 1.57077 5e-06 0.001285</pose>
          <velocity>0.000697 0.000835 -0.005147 -0.007055 0.004694 1.8e-05</velocity>
          <acceleration>-0.006871 0.010068 -9.79982 0.060746 0.000308 6.6e-05</acceleration>
          <wrench>-0.000182 0.000267 -0.260215 0 -0 0</wrench>
        </link>
        <link name='prop2'>
          <pose frame=''>-0.432791 0.250378 0.134286 1.57077 5e-06 0.00128</pose>
          <velocity>0.000574 0.000841 -0.008681 -0.007055 0.004694 1.8e-05</velocity>
          <acceleration>0.00336 0.009774 -9.79966 0.060828 0.00187 6.6e-05</acceleration>
          <wrench>8.9e-05 0.00026 -0.26021 0 -0 0</wrench>
        </link>
        <link name='prop3'>
          <pose frame=''>0.000433 0.500006 0.133976 1.57077 5e-06 0.001309</pose>
          <velocity>0.00051 0.000948 -0.012478 -0.007064 0.004695 1.8e-05</velocity>
          <acceleration>0.008441 -3.6e-05 -9.80036 0.005128 0.003082 6.6e-05</acceleration>
          <wrench>0.000224 -1e-06 -0.260229 0 -0 0</wrench>
        </link>
        <link name='prop4'>
          <pose frame=''>0.433229 0.249634 0.133982 1.57077 5e-06 0.001329</pose>
          <velocity>0.000573 0.001057 -0.012741 -0.007074 0.004695 1.9e-05</velocity>
          <acceleration>0.003366 -0.009797 -9.80172 -0.056894 0.002791 6.6e-05</acceleration>
          <wrench>8.9e-05 -0.00026 -0.260265 0 -0 0</wrench>
        </link>
        <link name='prop5'>
          <pose frame=''>0.432799 -0.250366 0.1349 1.57077 5e-06 0.001323</pose>
          <velocity>0.000703 0.001063 -0.009207 -0.007075 0.004695 1.9e-05</velocity>
          <acceleration>-0.006538 -0.009738 -9.80191 -0.058038 0.00412 6.6e-05</acceleration>
          <wrench>-0.000174 -0.000259 -0.26027 0 -0 0</wrench>
        </link>
        <link name='prop6'>
          <pose frame=''>-0.000425 -0.499994 0.13508 1.57077 5e-06 0.001308</pose>
          <velocity>0.000767 0.000956 -0.005409 -0.007064 0.004695 1.8e-05</velocity>
          <acceleration>-0.011249 5.1e-05 -9.7999 0.008495 0.005933 6.6e-05</acceleration>
          <wrench>-0.000299 1e-06 -0.260217 0 -0 0</wrench>
        </link>
      </model>
      <light name='sun'>
        <pose frame=''>0 0 10 0 -0 0</pose>
      </light>
    </state>
    <gui fullscreen='0'>
      <camera name='user_camera'>
        <pose frame=''>72.0818 -124.248 14.144 0 0.275643 2.35619</pose>
        <view_controller>orbit</view_controller>
        <projection_type>perspective</projection_type>
      </camera>
    </gui>
  </world>
</sdf>
